Workbook

Sheet ANT_pumpParticles_Export_v2
A1: GTNum | B1: StnCast | C1: Station | D1: CastType | E1: DepthFromBottom | F1: Lat | G1: Lon | H1: DistFromShore | I1: Depth | J1: Ag_SSF | K1: Al_SSF | L1: Ba_SSF | M1: Cd_SSF | N1: Ce_SSF | O1: Co_SSF | P1: Cr_SSF | Q1: Cu65_SSF | R1: Cu_SSF | S1: Dy161_SSF | T1: Dy_SSF | U1: Er167_SSF | V1: Er_SSF | W1: Eu153_SSF | X1: Eu_SSF | Y1: Fe57_SSF | Z1: Fe_SSF | AA1: Gd157_SSF | AB1: Gd_SSF | AC1: Ho_SSF | AD1: La_SSF | AE1: Lu_SSF | AF1: Mn_SSF | AG1: Mo_SSF | AH1: Nd143_SSF | AI1: Nd_SSF | AJ1: Ni_SSF | AK1: P_SSF | AL1: Pb_SSF | AM1: Pr_SSF | AN1: Rb_SSF | AO1: Re_SSF | AP1: Sc_SSF | AQ1: Sm149_SSF | AR1: Sm_SSF | AS1: Sr_SSF | AT1: Tb_SSF | AU1: Th_SSF | AV1: Ti_SSF | AW1: Tm_SSF | AX1: U_SSF | AY1: V_SSF | AZ1: Y_SSF | BA1: Yb172_SSF | BB1: Yb_SSF | BC1: Zn_SSF | BD1: Zr_SSF | BE1: Ag_LSF | BF1: Al_LSF | BG1: Ba_LSF | BH1: Cd_LSF | BI1: Ce_LSF | BJ1: Co_LSF | BK1: Cr_LSF | BL1: Cu65_LSF | BM1: Cu_LSF | BN1: Dy161_LSF | BO1: Dy_LSF | BP1: Er167_LSF | BQ1: Er_LSF | BR1: Eu153_LSF | BS1: Eu_LSF | BT1: Fe57_LSF | BU1: Fe_LSF | BV1: Gd157_LSF | BW1: Gd_LSF | BX1: Ho_LSF | BY1: La_LSF | BZ1: Lu_LSF | CA1: Mn_LSF | CB1: Mo_LSF | CC1: Nd143_LSF | CD1: Nd_LSF | CE1: Ni_LSF | CF1: P_LSF | CG1: Pb_LSF | CH1: Pr_LSF | CI1: Rb_LSF | CJ1: Re_LSF | CK1: Sc_LSF | CL1: Sm149_LSF | CM1: Sm_LSF | CN1: Sr_LSF | CO1: Tb_LSF | CP1: Th_LSF | CQ1: Ti_LSF | CR1: Tm_LSF | CS1: U_LSF | CT1: V_LSF | CU1: Y_LSF | CV1: Yb172_LSF | CW1: Yb_LSF | CX1: Zn_LSF | CY1: Zr_LSF | CZ1: Ag_LAB | DA1: Al_LAB | DB1: Ba_LAB | DC1: Cd_LAB | DD1: Ce_LAB | DE1: Co_LAB | DF1: Cr_LAB | DG1: Cu_LAB | DH1: Fe57_LAB | DI1: Fe_LAB | DJ1: La_LAB | DK1: Mn_LAB | DL1: Mo_LAB | DM1: Nd_LAB | DN1: Ni_LAB | DO1: P_LAB | DP1: Pb_LAB | DQ1: Pr_LAB | DR1: Sc_LAB | DS1: Sr_LAB | DT1: Th_LAB | DU1: Ti_LAB | DV1: V_LAB | DW1: Y_LAB | DX1: Yb_LAB | DY1: Zn_LAB | DZ1: =LEFT(CZ1,FIND("_",CZ1)-1)&"_REF" -> Ag_REF | EA1: =LEFT(DA1,FIND("_",DA1)-1)&"_REF" -> Al_REF | EB1: =LEFT(DB1,FIND("_",DB1)-1)&"_REF" -> Ba_REF | EC1: =LEFT(DC1,FIND("_",DC1)-1)&"_REF" -> Cd_REF | ED1: =LEFT(DD1,FIND("_",DD1)-1)&"_REF" -> Ce_REF | EE1: =LEFT(DE1,FIND("_",DE1)-1)&"_REF" -> Co_REF | EF1: =LEFT(DF1,FIND("_",DF1)-1)&"_REF" -> Cr_REF | EG1: =LEFT(DG1,FIND("_",DG1)-1)&"_REF" -> Cu_REF | ... EY1: =LEFT(DY1,FIND("_",DY1)-1)&"_REF" -> Zn_REF
A2: 18864 | B2: 3S | C2: 3 | D2: S | E2: -4689.3636 | F2: -67.0041 | G2: -100.035 | H2: 527.7803 | I2: 18.636364 | J2: 1.1866362 | K2: NaN | L2: 31.983794 | M2: 39.242305 | N2: 43.653259 | O2: 1.3795878 | P2: 4.7095691 | Q2: 34.182505 | R2: 30.929416 | S2: NaN | T2: NaN | U2: NaN | V2: 0.02406809 | W2: NaN | X2: NaN | Y2: 153.4683 | Z2: 161.50949 | AA2: NaN | AB2: NaN | AC2: NaN | AD2: 40.960876 | AE2: NaN | AF2: 21.531523 | AG2: NaN | AH2: NaN | AI2: NaN | AJ2: 15.229544 | AK2: 46932.905 | AL2: 0.78593338 | AM2: 0.003553618 | AN2: NaN | AO2: NaN | AP2: NaN | AQ2: NaN | AR2: NaN | AS2: 126.45141 | AT2: NaN | AU2: NaN | AV2: 26.386263 | AW2: NaN | AX2: 0.2047614 | AY2: 3.9536353 | AZ2: 0.060440821 | BA2: NaN | BB2: NaN | BC2: 277.62282 | BD2: 0.65792593 | BE2: 0.021573933 | BF2: 19.218383 | BG2: 36.794 | BH2: 1.3106593 | BI2: 37.715022 | BJ2: NaN | BK2: 0.17992667 | BL2: 3.7468 | BM2: 3.6229292 | BN2: NaN | BO2: NaN | BP2: NaN | BQ2: 0.00274118 | BR2: NaN | BS2: NaN | BT2: 22.050494 | BU2: 21.550979 | BV2: NaN | BW2: NaN | BX2: NaN | BY2: 37.742613 | BZ2: NaN | CA2: 1.8151216 | CB2: 0.032522577 | CC2: NaN | CD2: NaN | CE2: NaN | CF2: 2747.1938 | CG2: 0.13217679 | CH2: 0.001475792 | CI2: 0.4315373 | CJ2: 0.001944555 | CK2: NaN | CL2: NaN | CM2: 0.044712106 | CN2: 33.316381 | CO2: NaN | CP2: NaN | CQ2: 17.878288 | CR2: NaN | CS2: 0.084591383 | CT2: 2.0510876 | CU2: NaN | CV2: NaN | CW2: NaN | CX2: 69.603817 | CY2: 0.01860358 | CZ2: 1.6022345 | DA2: 116.77831 | DB2: 7.2159785 | DC2: 42.312978 | DD2: 0.023433641 | DE2: 1.0450982 | DF2: NaN | DG2: 29.104223 | DH2: 63.582037 | DI2: 62.93452 | DJ2: 0.022889685 | DK2: 31.70798 | DL2: NaN | DM2: 0.011352366 | DN2: 15.846845 | DO2: 51589.409 | DP2: 0.44474578 | DQ2: 0.0016154558 | DR2: 0.029404643 | DS2: NaN | DT2: 0.0024630405 | DU2: NaN | DV2: 9.9939129 | DW2: 0.12728802 | DX2: 0.0087344262 | DY2: 367.08052 | DZ2: =IFERROR(IF(BE2<J2,BE2*-1+J2,"NaN"),"NaN") -> 1.1650623 | EA2: =IFERROR(IF(BF2<K2,BF2*-1+K2,"NaN"),"NaN") -> NaN | EB2: =IFERROR(IF(BG2<L2,BG2*-1+L2,"NaN"),"NaN") -> NaN | EC2: =IFERROR(IF(BH2<M2,BH2*-1+M2,"NaN"),"NaN") -> 37.931646 | ED2: =IFERROR(IF(BI2<N2,BI2*-1+N2,"NaN"),"NaN") -> 5.9382367 | EE2: =IFERROR(IF(BJ2<O2,BJ2*-1+O2,"NaN"),"NaN") -> NaN | EF2: =IFERROR(IF(BK2<P2,BK2*-1+P2,"NaN"),"NaN") -> 4.5296424 | EG2: =IFERROR(IF(BL2<R2,BL2*-1+R2,"NaN"),"NaN") -> 27.182616 | EH2: =IFERROR(IF(BM2<Y2,BM2*-1+Y2,"NaN"),"NaN") -> 149.84537 | EI2: =IFERROR(IF(BN2<Z2,BN2*-1+Z2,"NaN"),"NaN") -> NaN | EJ2: =IFERROR(IF(BO2<AD2,BO2*-1+AD2,"NaN"),"NaN") -> NaN | EK2: =IFERROR(IF(BP2<AF2,BP2*-1+AF2,"NaN"),"NaN") -> NaN | EL2: =IFERROR(IF(BQ2<AG2,BQ2*-1+AG2,"NaN"),"NaN") -> NaN | EM2: =IFERROR(IF(BR2<AI2,BR2*-1+AI2,"NaN"),"NaN") -> NaN | EN2: =IFERROR(IF(BS2<AJ2,BS2*-1+AJ2,"NaN"),"NaN") -> NaN | EO2: =IFERROR(IF(BT2<AK2,BT2*-1+AK2,"NaN"),"NaN") -> 46910.855 | EP2: =IFERROR(IF(BU2<AL2,BU2*-1+AL2,"NaN"),"NaN") -> NaN | EQ2: =IFERROR(IF(BV2<AM2,BV2*-1+AM2,"NaN"),"NaN") -> NaN | ER2: =IFERROR(IF(BW2<AP2,BW2*-1+AP2,"NaN"),"NaN") -> NaN | ES2: =IFERROR(IF(BX2<AS2,BX2*-1+AS2,"NaN"),"NaN") -> NaN | ET2: =IFERROR(IF(BY2<AU2,BY2*-1+AU2,"NaN"),"NaN") -> NaN | EU2: =IFERROR(IF(BZ2<AV2,BZ2*-1+AV2,"NaN"),"NaN") -> NaN | EV2: =IFERROR(IF(CA2<AY2,CA2*-1+AY2,"NaN"),"NaN") -> 2.1385137 | EW2: =IFERROR(IF(CB2<AZ2,CB2*-1+AZ2,"NaN"),"NaN") -> 0.027918244 | EX2: =IFERROR(IF(CC2<BB2,CC2*-1+BB2,"NaN"),"NaN") -> NaN | EY2: =IFERROR(IF(CD2<BC2,CD2*-1+BC2,"NaN"),"NaN") -> NaN
A3: 18865 | B3: 3S | C3: 3 | D3: S | E3: -4670.7273 | F3: -67.0041 | G3: -100.035 | H3: 527.7803 | I3: 37.272727 | J3: 1.0782361 | K3: NaN | L3: 23.015738 | M3: 43.744499 | N3: 30.401286 | O3: 1.0136987 | P3: NaN | Q3: 38.648669 | R3: 34.578959 | S3: NaN | T3: NaN | U3: NaN | V3: 0.05198738 | W3: NaN | X3: NaN | Y3: 19.72447 | Z3: 21.220681 | AA3: NaN | AB3: NaN | AC3: NaN | AD3: 28.507326 | AE3: NaN | AF3: 26.803599 | AG3: NaN | AH3: NaN | AI3: NaN | AJ3: 2.2554 | AK3: 42475.98 | AL3: 0.37180335 | AM3: NaN | AN3: NaN | AO3: NaN | AP3: NaN | AQ3: NaN | AR3: NaN | AS3: 771.66824 | AT3: NaN | AU3: NaN | AV3: 8.541602 | AW3: NaN | AX3: 0.1502803 | AY3: 3.392432 | AZ3: 0.04156313 | BA3: NaN | BB3: NaN | BC3: 285.06957 | BD3: 0.21064386 | BE3: 0.058940512 | BF3: 54.952179 | BG3: 26.35533 | BH3: 2.268208 | BI3: 27.778827 | BJ3: 0.020605318 | BK3: 12.257548 | BL3: 4.4850702 | BM3: 4.470178 | BN3: NaN | BO3: NaN | BP3: NaN | BQ3: 0.003120626 | BR3: NaN | BS3: NaN | BT3: 183.45276 | BU3: 183.30957 | BV3: NaN | BW3: NaN | BX3: NaN | BY3: 27.61662 | BZ3: NaN | CA3: 4.9911342 | CB3: 0.64109269 | CC3: NaN | CD3: NaN | CE3: NaN | CF3: 4484.9978 | CG3: 0.24538287 | CH3: NaN | CI3: 0.66143956 | CJ3: 0.001895377 | CK3: NaN | CL3: NaN | CM3: 0.043430668 | CN3: 63.063893 | CO3: NaN | CP3: NaN | CQ3: 29.892612 | CR3: NaN | CS3: 0.083748019 | CT3: 2.1044596 | CU3: NaN | CV3: NaN | CW3: NaN | CX3: 43.967836 | CY3: NaN | CZ3: 1.3317043 | DA3: 120.10116 | DB3: 6.2057994 | DC3: 39.993982 | DD3: 0.041781813 | DE3: 0.93839121 | DF3: NaN | DG3: 28.403066 | DH3: 19.307289 | DI3: 17.776771 | DJ3: 0.027533772 | DK3: 25.897353 | DL3: NaN | DM3: 0.017091618 | DN3: 11.951371 | DO3: 42155.18 | DP3: 0.13304428 | DQ3: 0.0030857964 | DR3: 0.016740781 | DS3: 584.5275 | DT3: 0.0037896257 | DU3: NaN | DV3: 8.9220106 | DW3: 0.17559497 | DX3: 0.011488935 | DY3: 354.93548 | DZ3: =IFERROR(IF(BE3<J3,BE3*-1+J3,"NaN"),"NaN") -> 1.0192956 | EA3: =IFERROR(IF(BF3<K3,BF3*-1+K3,"NaN"),"NaN") -> NaN | EB3: =IFERROR(IF(BG3<L3,BG3*-1+L3,"NaN"),"NaN") -> NaN | EC3: =IFERROR(IF(BH3<M3,BH3*-1+M3,"NaN"),"NaN") -> 41.476291 | ED3: =IFERROR(IF(BI3<N3,BI3*-1+N3,"NaN"),"NaN") -> 2.622459 | EE3: =IFERROR(IF(BJ3<O3,BJ3*-1+O3,"NaN"),"NaN") -> 0.99309342 | EF3: =IFERROR(IF(BK3<P3,BK3*-1+P3,"NaN"),"NaN") -> NaN | EG3: =IFERROR(IF(BL3<R3,BL3*-1+R3,"NaN"),"NaN") -> 30.093889 | EH3: =IFERROR(IF(BM3<Y3,BM3*-1+Y3,"NaN"),"NaN") -> 15.254292 | EI3: =IFERROR(IF(BN3<Z3,BN3*-1+Z3,"NaN"),"NaN") -> NaN | EJ3: =IFERROR(IF(BO3<AD3,BO3*-1+AD3,"NaN"),"NaN") -> NaN | EK3: =IFERROR(IF(BP3<AF3,BP3*-1+AF3,"NaN"),"NaN") -> NaN | EL3: =IFERROR(IF(BQ3<AG3,BQ3*-1+AG3,"NaN"),"NaN") -> NaN | EM3: =IFERROR(IF(BR3<AI3,BR3*-1+AI3,"NaN"),"NaN") -> NaN | EN3: =IFERROR(IF(BS3<AJ3,BS3*-1+AJ3,"NaN"),"NaN") -> NaN | EO3: =IFERROR(IF(BT3<AK3,BT3*-1+AK3,"NaN"),"NaN") -> 42292.527 | EP3: =IFERROR(IF(BU3<AL3,BU3*-1+AL3,"NaN"),"NaN") -> NaN | EQ3: =IFERROR(IF(BV3<AM3,BV3*-1+AM3,"NaN"),"NaN") -> NaN | ER3: =IFERROR(IF(BW3<AP3,BW3*-1+AP3,"NaN"),"NaN") -> NaN | ES3: =IFERROR(IF(BX3<AS3,BX3*-1+AS3,"NaN"),"NaN") -> NaN | ET3: =IFERROR(IF(BY3<AU3,BY3*-1+AU3,"NaN"),"NaN") -> NaN | EU3: =IFERROR(IF(BZ3<AV3,BZ3*-1+AV3,"NaN"),"NaN") -> NaN | EV3: =IFERROR(IF(CA3<AY3,CA3*-1+AY3,"NaN"),"NaN") -> NaN | EW3: =IFERROR(IF(CB3<AZ3,CB3*-1+AZ3,"NaN"),"NaN") -> NaN | EX3: =IFERROR(IF(CC3<BB3,CC3*-1+BB3,"NaN"),"NaN") -> NaN | EY3: =IFERROR(IF(CD3<BC3,CD3*-1+BC3,"NaN"),"NaN") -> NaN
A4: 18866 | B4: 3S | C4: 3 | D4: S | E4: -4644.6364 | F4: -67.0041 | G4: -100.035 | H4: 527.7803 | I4: 63.363636 | J4: NaN | K4: NaN | L4: NaN | M4: 119.87865 | N4: 144.25007 | O4: NaN | P4: NaN | Q4: NaN | R4: NaN | S4: NaN | T4: NaN | U4: NaN | V4: 10.189654 | W4: NaN | X4: NaN | Y4: 6479.6536 | Z4: 6601.7823 | AA4: NaN | AB4: NaN | AC4: NaN | AD4: 86.501968 | AE4: NaN | AF4: 122.78202 | AG4: NaN | AH4: NaN | AI4: NaN | AJ4: NaN | AK4: 114494.9 | AL4: 97.871571 | AM4: NaN | AN4: NaN | AO4: NaN | AP4: NaN | AQ4: NaN | AR4: NaN | AS4: NaN | AT4: NaN | AU4: NaN | AV4: 2774.2481 | AW4: NaN | AX4: NaN | AY4: NaN | AZ4: NaN | BA4: NaN | BB4: NaN | BC4: 310.83696 | BD4: 195.21015 | BE4: NaN | BF4: NaN | BG4: 175.44881 | BH4: 11.739964 | BI4: 194.36533 | BJ4: NaN | BK4: 675.2867 | BL4: 29.186938 | BM4: 30.832293 | BN4: NaN | BO4: NaN | BP4: NaN | BQ4: 0.098081619 | BR4: NaN | BS4: NaN | BT4: 2840.43 | BU4: 2936.0369 | BV4: NaN | BW4: NaN | BX4: NaN | BY4: 197.16547 | BZ4: NaN | CA4: 1.2563588 | CB4: 3.3771965 | CC4: NaN | CD4: NaN | CE4: NaN | CF4: 18685.506 | CG4: 2.395684 | CH4: NaN | CI4: NaN | CJ4: 0.11168629 | CK4: NaN | CL4: NaN | CM4: 2.1155095 | CN4: NaN | CO4: NaN | CP4: NaN | CQ4: 220.44894 | CR4: NaN | CS4: 0.13468871 | CT4: NaN | CU4: NaN | CV4: NaN | CW4: NaN | CX4: 1749.0595 | CY4: NaN | CZ4: NaN | DA4: NaN | DB4: NaN | DC4: NaN | DD4: NaN | DE4: NaN | DF4: NaN | DG4: NaN | DH4: NaN | DI4: NaN | DJ4: NaN | DK4: NaN | DL4: NaN | DM4: NaN | DN4: NaN | DO4: NaN | DP4: NaN | DQ4: NaN | DR4: NaN | DS4: NaN | DT4: NaN | DU4: NaN | DV4: NaN | DW4: NaN | DX4: NaN | DY4: NaN | DZ4: =IFERROR(IF(BE4<J4,BE4*-1+J4,"NaN"),"NaN") -> NaN | EA4: =IFERROR(IF(BF4<K4,BF4*-1+K4,"NaN"),"NaN") -> NaN | EB4: =IFERROR(IF(BG4<L4,BG4*-1+L4,"NaN"),"NaN") -> NaN | EC4: =IFERROR(IF(BH4<M4,BH4*-1+M4,"NaN"),"NaN") -> 108.13869 | ED4: =IFERROR(IF(BI4<N4,BI4*-1+N4,"NaN"),"NaN") -> NaN | EE4: =IFERROR(IF(BJ4<O4,BJ4*-1+O4,"NaN"),"NaN") -> NaN | EF4: =IFERROR(IF(BK4<P4,BK4*-1+P4,"NaN"),"NaN") -> NaN | EG4: =IFERROR(IF(BL4<R4,BL4*-1+R4,"NaN"),"NaN") -> NaN | EH4: =IFERROR(IF(BM4<Y4,BM4*-1+Y4,"NaN"),"NaN") -> 6448.8213 | EI4: =IFERROR(IF(BN4<Z4,BN4*-1+Z4,"NaN"),"NaN") -> NaN | EJ4: =IFERROR(IF(BO4<AD4,BO4*-1+AD4,"NaN"),"NaN") -> NaN | EK4: =IFERROR(IF(BP4<AF4,BP4*-1+AF4,"NaN"),"NaN") -> NaN | EL4: =IFERROR(IF(BQ4<AG4,BQ4*-1+AG4,"NaN"),"NaN") -> NaN | EM4: =IFERROR(IF(BR4<AI4,BR4*-1+AI4,"NaN"),"NaN") -> NaN | EN4: =IFERROR(IF(BS4<AJ4,BS4*-1+AJ4,"NaN"),"NaN") -> NaN | EO4: =IFERROR(IF(BT4<AK4,BT4*-1+AK4,"NaN"),"NaN") -> 111654.47 | EP4: =IFERROR(IF(BU4<AL4,BU4*-1+AL4,"NaN"),"NaN") -> NaN | EQ4: =IFERROR(IF(BV4<AM4,BV4*-1+AM4,"NaN"),"NaN") -> NaN | ER4: =IFERROR(IF(BW4<AP4,BW4*-1+AP4,"NaN"),"NaN") -> NaN | ES4: =IFERROR(IF(BX4<AS4,BX4*-1+AS4,"NaN"),"NaN") -> NaN | ET4: =IFERROR(IF(BY4<AU4,BY4*-1+AU4,"NaN"),"NaN") -> NaN | EU4: =IFERROR(IF(BZ4<AV4,BZ4*-1+AV4,"NaN"),"NaN") -> NaN | EV4: =IFERROR(IF(CA4<AY4,CA4*-1+AY4,"NaN"),"NaN") -> NaN | EW4: =IFERROR(IF(CB4<AZ4,CB4*-1+AZ4,"NaN"),"NaN") -> NaN | EX4: =IFERROR(IF(CC4<BB4,CC4*-1+BB4,"NaN"),"NaN") -> NaN | EY4: =IFERROR(IF(CD4<BC4,CD4*-1+BC4,"NaN"),"NaN") -> NaN
A5: 18867 | B5: 3S | C5: 3 | D5: S | E5: -4577.5455 | F5: -67.0041 | G5: -100.035 | H5: 527.7803 | I5: 130.45455 | J5: 0.39508768 | K5: NaN | L5: 128.62679 | M5: 7.8734661 | N5: 173.75208 | O5: 0.2542123 | P5: NaN | Q5: 47.30637 | R5: 42.888868 | S5: NaN | T5: NaN | U5: NaN | V5: 0.043745652 | W5: NaN | X5: NaN | Y5: 39.814972 | Z5: 42.528799 | AA5: NaN | AB5: NaN | AC5: NaN | AD5: 163.90874 | AE5: NaN | AF5: 8.2348219 | AG5: NaN | AH5: NaN | AI5: NaN | AJ5: 0.24604635 | AK5: 5721.2146 | AL5: 0.16106429 | AM5: 0.008326906 | AN5: NaN | AO5: NaN | AP5: NaN | AQ5: NaN | AR5: NaN | AS5: 120.58804 | AT5: NaN | AU5: NaN | AV5: 10.499317 | AW5: NaN | AX5: NaN | AY5: 0.98813733 | AZ5: 0.011314392 | BA5: NaN | BB5: NaN | BC5: 53.684035 | BD5: NaN | BE5: NaN | BF5: 12.790096 | BG5: 0.97334429 | BH5: 0.057666823 | BI5: 1.0790896 | BJ5: NaN | BK5: 4.0552484 | BL5: 17.334107 | BM5: 17.402139 | BN5: NaN | BO5: NaN | BP5: NaN | BQ5: 0.000366283 | BR5: NaN | BS5: NaN | BT5: 16.32832 | BU5: 17.182373 | BV5: NaN | BW5: NaN | BX5: NaN | BY5: 1.0591505 | BZ5: NaN | CA5: 0.068441642 | CB5: 0.010160315 | CC5: NaN | CD5: NaN | CE5: NaN | CF5: 119.47259 | CG5: 0.025065054 | CH5: NaN | CI5: NaN | CJ5: 0.00088301 | CK5: NaN | CL5: NaN | CM5: 0.011846369 | CN5: NaN | CO5: NaN | CP5: NaN | CQ5: 1.2644944 | CR5: NaN | CS5: 0.001019936 | CT5: 0.006789339 | CU5: NaN | CV5: NaN | CW5: NaN | CX5: 6.1359608 | CY5: NaN | CZ5: 0.49667481 | DA5: 54.439799 | DB5: 34.222612 | DC5: 6.8902262 | DD5: 0.014144185 | DE5: 0.21146571 | DF5: NaN | DG5: 139.35003 | DH5: 36.837263 | DI5: 36.974017 | DJ5: 0.060175971 | DK5: 5.1715697 | DL5: NaN | DM5: 0.018427635 | DN5: 4.2917765 | DO5: 4619.1963 | DP5: 0.054313353 | DQ5: 0.003221613 | DR5: 0.00052969035 | DS5: 73.379323 | DT5: 0.0011714347 | DU5: NaN | DV5: 3.4957403 | DW5: 0.11142582 | DX5: 0.0052240816 | DY5: 61.861512 | DZ5: =IFERROR(IF(BE5<J5,BE5*-1+J5,"NaN"),"NaN") -> NaN | EA5: =IFERROR(IF(BF5<K5,BF5*-1+K5,"NaN"),"NaN") -> NaN | EB5: =IFERROR(IF(BG5<L5,BG5*-1+L5,"NaN"),"NaN") -> 127.65345 | EC5: =IFERROR(IF(BH5<M5,BH5*-1+M5,"NaN"),"NaN") -> 7.8157992 | ED5: =IFERROR(IF(BI5<N5,BI5*-1+N5,"NaN"),"NaN") -> 172.673 | EE5: =IFERROR(IF(BJ5<O5,BJ5*-1+O5,"NaN"),"NaN") -> NaN | EF5: =IFERROR(IF(BK5<P5,BK5*-1+P5,"NaN"),"NaN") -> NaN | EG5: =IFERROR(IF(BL5<R5,BL5*-1+R5,"NaN"),"NaN") -> 25.554761 | EH5: =IFERROR(IF(BM5<Y5,BM5*-1+Y5,"NaN"),"NaN") -> 22.412834 | EI5: =IFERROR(IF(BN5<Z5,BN5*-1+Z5,"NaN"),"NaN") -> NaN | EJ5: =IFERROR(IF(BO5<AD5,BO5*-1+AD5,"NaN"),"NaN") -> NaN | EK5: =IFERROR(IF(BP5<AF5,BP5*-1+AF5,"NaN"),"NaN") -> NaN | EL5: =IFERROR(IF(BQ5<AG5,BQ5*-1+AG5,"NaN"),"NaN") -> NaN | EM5: =IFERROR(IF(BR5<AI5,BR5*-1+AI5,"NaN"),"NaN") -> NaN | EN5: =IFERROR(IF(BS5<AJ5,BS5*-1+AJ5,"NaN"),"NaN") -> NaN | EO5: =IFERROR(IF(BT5<AK5,BT5*-1+AK5,"NaN"),"NaN") -> 5704.8862 | EP5: =IFERROR(IF(BU5<AL5,BU5*-1+AL5,"NaN"),"NaN") -> NaN | EQ5: =IFERROR(IF(BV5<AM5,BV5*-1+AM5,"NaN"),"NaN") -> NaN | ER5: =IFERROR(IF(BW5<AP5,BW5*-1+AP5,"NaN"),"NaN") -> NaN | ES5: =IFERROR(IF(BX5<AS5,BX5*-1+AS5,"NaN"),"NaN") -> NaN | ET5: =IFERROR(IF(BY5<AU5,BY5*-1+AU5,"NaN"),"NaN") -> NaN | EU5: =IFERROR(IF(BZ5<AV5,BZ5*-1+AV5,"NaN"),"NaN") -> NaN | EV5: =IFERROR(IF(CA5<AY5,CA5*-1+AY5,"NaN"),"NaN") -> 0.91969569 | EW5: =IFERROR(IF(CB5<AZ5,CB5*-1+AZ5,"NaN"),"NaN") -> 0.001154077 | EX5: =IFERROR(IF(CC5<BB5,CC5*-1+BB5,"NaN"),"NaN") -> NaN | EY5: =IFERROR(IF(CD5<BC5,CD5*-1+BC5,"NaN"),"NaN") -> NaN
A6: 18868 | B6: 3S | C6: 3 | D6: S | E6: -4532.8182 | F6: -67.0041 | G6: -100.035 | H6: 527.7803 | I6: 175.18182 | J6: 0.38702747 | K6: NaN | L6: 245.08499 | M6: 5.2316876 | N6: 330.08778 | O6: 0.16645519 | P6: NaN | Q6: 29.501891 | R6: 25.947005 | S6: NaN | T6: NaN | U6: 0.001623345 | V6: 0.011684123 | W6: 0.000237642 | X6: 0.005786821 | Y6: 33.166081 | Z6: 34.636892 | AA6: 0.008149808 | AB6: NaN | AC6: 0.001838812 | AD6: 309.29194 | AE6: 0.002320547 | AF6: 14.56326 | AG6: NaN | AH6: 0.00295332 | AI6: 0.017274557 | AJ6: 3.1936423 | AK6: 2665.4055 | AL6: 0.088409481 | AM6: 0.051114485 | AN6: NaN | AO6: NaN | AP6: NaN | AQ6: 0.001329087 | AR6: 0.01308642 | AS6: 344.40361 | AT6: NaN | AU6: NaN | AV6: 3.3496564 | AW6: 0.000596575 | AX6: 0.029271377 | AY6: 2.9924158 | AZ6: 0.07376047 | BA6: 0.000311456 | BB6: 0.001045679 | BC6: 34.904599 | BD6: 0.002798007 | BE6: 0.001780763 | BF6: 14.14342 | BG6: 8.4670716 | BH6: 0.084495363 | BI6: 8.7445933 | BJ6: NaN | BK6: NaN | BL6: 0.34291497 | BM6: 0.32593101 | BN6: NaN | BO6: NaN | BP6: NaN | BQ6: 0.000146717 | BR6: NaN | BS6: NaN | BT6: 16.490377 | BU6: 15.449061 | BV6: NaN | BW6: NaN | BX6: NaN | BY6: 8.7204709 | BZ6: NaN | CA6: 0.18635272 | CB6: 0.027724954 | CC6: NaN | CD6: NaN | CE6: NaN | CF6: 120.01968 | CG6: 0.008102594 | CH6: NaN | CI6: NaN | CJ6: 0.000152155 | CK6: NaN | CL6: NaN | CM6: 0.003928557 | CN6: 43.791855 | CO6: NaN | CP6: NaN | CQ6: 1.5153723 | CR6: NaN | CS6: 0.003362613 | CT6: 0.10079651 | CU6: NaN | CV6: NaN | CW6: NaN | CX6: 2.2219041 | CY6: 0.00134071 | CZ6: 0.38611656 | DA6: 19.572748 | DB6: 26.818219 | DC6: 4.0107964 | DD6: 0.048470619 | DE6: 0.13981739 | DF6: NaN | DG6: 12.993396 | DH6: 29.170964 | DI6: 28.291292 | DJ6: 0.057274302 | DK6: 13.541021 | DL6: NaN | DM6: 0.024784852 | DN6: 3.3130592 | DO6: 1773.7756 | DP6: 0.050141072 | DQ6: 0.0058779947 | DR6: 0.010983391 | DS6: 156.19704 | DT6: 0.00030667092 | DU6: NaN | DV6: 4.6176169 | DW6: 0.097836146 | DX6: 0.0041472631 | DY6: 25.927914 | DZ6: =IFERROR(IF(BE6<J6,BE6*-1+J6,"NaN"),"NaN") -> 0.38524671 | EA6: =IFERROR(IF(BF6<K6,BF6*-1+K6,"NaN"),"NaN") -> NaN | EB6: =IFERROR(IF(BG6<L6,BG6*-1+L6,"NaN"),"NaN") -> 236.61791 | EC6: =IFERROR(IF(BH6<M6,BH6*-1+M6,"NaN"),"NaN") -> 5.1471923 | ED6: =IFERROR(IF(BI6<N6,BI6*-1+N6,"NaN"),"NaN") -> 321.34319 | EE6: =IFERROR(IF(BJ6<O6,BJ6*-1+O6,"NaN"),"NaN") -> NaN | EF6: =IFERROR(IF(BK6<P6,BK6*-1+P6,"NaN"),"NaN") -> NaN | EG6: =IFERROR(IF(BL6<R6,BL6*-1+R6,"NaN"),"NaN") -> 25.60409 | EH6: =IFERROR(IF(BM6<Y6,BM6*-1+Y6,"NaN"),"NaN") -> 32.84015 | EI6: =IFERROR(IF(BN6<Z6,BN6*-1+Z6,"NaN"),"NaN") -> NaN | EJ6: =IFERROR(IF(BO6<AD6,BO6*-1+AD6,"NaN"),"NaN") -> NaN | EK6: =IFERROR(IF(BP6<AF6,BP6*-1+AF6,"NaN"),"NaN") -> NaN | EL6: =IFERROR(IF(BQ6<AG6,BQ6*-1+AG6,"NaN"),"NaN") -> NaN | EM6: =IFERROR(IF(BR6<AI6,BR6*-1+AI6,"NaN"),"NaN") -> NaN | EN6: =IFERROR(IF(BS6<AJ6,BS6*-1+AJ6,"NaN"),"NaN") -> NaN | EO6: =IFERROR(IF(BT6<AK6,BT6*-1+AK6,"NaN"),"NaN") -> 2648.9151 | EP6: =IFERROR(IF(BU6<AL6,BU6*-1+AL6,"NaN"),"NaN") -> NaN | EQ6: =IFERROR(IF(BV6<AM6,BV6*-1+AM6,"NaN"),"NaN") -> NaN | ER6: =IFERROR(IF(BW6<AP6,BW6*-1+AP6,"NaN"),"NaN") -> NaN | ES6: =IFERROR(IF(BX6<AS6,BX6*-1+AS6,"NaN"),"NaN") -> NaN | ET6: =IFERROR(IF(BY6<AU6,BY6*-1+AU6,"NaN"),"NaN") -> NaN | EU6: =IFERROR(IF(BZ6<AV6,BZ6*-1+AV6,"NaN"),"NaN") -> NaN | EV6: =IFERROR(IF(CA6<AY6,CA6*-1+AY6,"NaN"),"NaN") -> 2.8060631 | EW6: =IFERROR(IF(CB6<AZ6,CB6*-1+AZ6,"NaN"),"NaN") -> 0.046035516 | EX6: =IFERROR(IF(CC6<BB6,CC6*-1+BB6,"NaN"),"NaN") -> NaN | EY6: =IFERROR(IF(CD6<BC6,CD6*-1+BC6,"NaN"),"NaN") -> NaN
A7: 18869 | B7: 3S | C7: 3 | D7: S | E7: -4279.3636 | F7: -67.0041 | G7: -100.035 | H7: 527.7803 | I7: 428.63636 | J7: 0.21130198 | K7: 18.866293 | L7: 229.59025 | M7: 1.129141 | N7: 301.92928 | O7: 0.091336822 | P7: NaN | Q7: 25.128265 | R7: 22.535887 | S7: NaN | T7: NaN | U7: 0.001219173 | V7: 0.013456637 | W7: NaN | X7: 0.003955526 | Y7: 26.125582 | Z7: 26.345303 | AA7: NaN | AB7: NaN | AC7: 0.000334446 | AD7: 288.6933 | AE7: 0.000779856 | AF7: 11.419023 | AG7: NaN | AH7: 0.001324515 | AI7: 0.010875424 | AJ7: 3.1216152 | AK7: 1154.9761 | AL7: 0.040851086 | AM7: 0.024531935 | AN7: NaN | AO7: NaN | AP7: NaN | AQ7: NaN | AR7: 0.004539718 | AS7: 31.968729 | AT7: NaN | AU7: NaN | AV7: 4.5718764 | AW7: NaN | AX7: 0.011837025 | AY7: 0.60163936 | AZ7: 0.055838807 | BA7: NaN | BB7: NaN | BC7: 14.961387 | BD7: 0.000510751 | BE7: 0.011615799 | BF7: 62.221952 | BG7: 18.148515 | BH7: 0.058968661 | BI7: 18.635332 | BJ7: NaN | BK7: 0.32883675 | BL7: 2.3173035 | BM7: 2.2653674 | BN7: NaN | BO7: NaN | BP7: NaN | BQ7: 0.000171997 | BR7: NaN | BS7: 0.000725216 | BT7: 38.421261 | BU7: 38.95653 | BV7: NaN | BW7: NaN | BX7: NaN | BY7: 18.593166 | BZ7: NaN | CA7: 1.058935 | CB7: 0.005797809 | CC7: NaN | CD7: 0.000247952 | CE7: NaN | CF7: 185.48464 | CG7: 0.028196795 | CH7: NaN | CI7: 0.00690831 | CJ7: NaN | CK7: NaN | CL7: NaN | CM7: 0.00421874 | CN7: 56.715972 | CO7: NaN | CP7: NaN | CQ7: 4.8220458 | CR7: NaN | CS7: 0.012332784 | CT7: 0.20948141 | CU7: 0.004818472 | CV7: NaN | CW7: NaN | CX7: 3.9777444 | CY7: 0.008226541 | CZ7: 0.2894558 | DA7: 43.252827 | DB7: 27.584745 | DC7: 1.1835646 | DD7: 0.11003554 | DE7: 0.10791244 | DF7: NaN | DG7: 16.141655 | DH7: 33.434203 | DI7: 34.220782 | DJ7: 0.063753481 | DK7: 15.08941 | DL7: NaN | DM7: 0.038264305 | DN7: 3.7393981 | DO7: 1056.6177 | DP7: 0.039821365 | DQ7: 0.0088616033 | DR7: 0.04454817 | DS7: 203.45431 | DT7: 0.00064009968 | DU7: NaN | DV7: 2.0030716 | DW7: 0.1495659 | DX7: 0.0063274148 | DY7: 13.756796 | DZ7: =IFERROR(IF(BE7<J7,BE7*-1+J7,"NaN"),"NaN") -> 0.19968618 | EA7: =IFERROR(IF(BF7<K7,BF7*-1+K7,"NaN"),"NaN") -> NaN | EB7: =IFERROR(IF(BG7<L7,BG7*-1+L7,"NaN"),"NaN") -> 211.44173 | EC7: =IFERROR(IF(BH7<M7,BH7*-1+M7,"NaN"),"NaN") -> 1.0701724 | ED7: =IFERROR(IF(BI7<N7,BI7*-1+N7,"NaN"),"NaN") -> 283.29395 | EE7: =IFERROR(IF(BJ7<O7,BJ7*-1+O7,"NaN"),"NaN") -> NaN | EF7: =IFERROR(IF(BK7<P7,BK7*-1+P7,"NaN"),"NaN") -> NaN | EG7: =IFERROR(IF(BL7<R7,BL7*-1+R7,"NaN"),"NaN") -> 20.218584 | EH7: =IFERROR(IF(BM7<Y7,BM7*-1+Y7,"NaN"),"NaN") -> 23.860215 | EI7: =IFERROR(IF(BN7<Z7,BN7*-1+Z7,"NaN"),"NaN") -> NaN | EJ7: =IFERROR(IF(BO7<AD7,BO7*-1+AD7,"NaN"),"NaN") -> NaN | EK7: =IFERROR(IF(BP7<AF7,BP7*-1+AF7,"NaN"),"NaN") -> NaN | EL7: =IFERROR(IF(BQ7<AG7,BQ7*-1+AG7,"NaN"),"NaN") -> NaN | EM7: =IFERROR(IF(BR7<AI7,BR7*-1+AI7,"NaN"),"NaN") -> NaN | EN7: =IFERROR(IF(BS7<AJ7,BS7*-1+AJ7,"NaN"),"NaN") -> 3.1208899 | EO7: =IFERROR(IF(BT7<AK7,BT7*-1+AK7,"NaN"),"NaN") -> 1116.5548 | EP7: =IFERROR(IF(BU7<AL7,BU7*-1+AL7,"NaN"),"NaN") -> NaN | EQ7: =IFERROR(IF(BV7<AM7,BV7*-1+AM7,"NaN"),"NaN") -> NaN | ER7: =IFERROR(IF(BW7<AP7,BW7*-1+AP7,"NaN"),"NaN") -> NaN | ES7: =IFERROR(IF(BX7<AS7,BX7*-1+AS7,"NaN"),"NaN") -> NaN | ET7: =IFERROR(IF(BY7<AU7,BY7*-1+AU7,"NaN"),"NaN") -> NaN | EU7: =IFERROR(IF(BZ7<AV7,BZ7*-1+AV7,"NaN"),"NaN") -> NaN | EV7: =IFERROR(IF(CA7<AY7,CA7*-1+AY7,"NaN"),"NaN") -> NaN | EW7: =IFERROR(IF(CB7<AZ7,CB7*-1+AZ7,"NaN"),"NaN") -> 0.050040998 | EX7: =IFERROR(IF(CC7<BB7,CC7*-1+BB7,"NaN"),"NaN") -> NaN | EY7: =IFERROR(IF(CD7<BC7,CD7*-1+BC7,"NaN"),"NaN") -> 14.961139
A8: 18870 | B8: 3S | C8: 3 | D8: S | E8: -4148.9091 | F8: -67.0041 | G8: -100.035 | H8: 527.7803 | I8: 559.09091 | J8: 0.16199394 | K8: 80.876624 | L8: 297.62563 | M8: 0.74651639 | N8: 396.20759 | O8: 0.12349865 | P8: NaN | Q8: 26.039423 | R8: 23.580501 | S8: NaN | T8: NaN | U8: NaN | V8: 0.001758787 | W8: NaN | X8: 0.009222585 | Y8: 39.032517 | Z8: 42.943398 | AA8: NaN | AB8: NaN | AC8: NaN | AD8: 377.80118 | AE8: NaN | AF8: 11.216612 | AG8: NaN | AH8: 0.005554799 | AI8: 0.026641581 | AJ8: 3.5732705 | AK8: 969.78258 | AL8: 0.07422978 | AM8: 0.04904843 | AN8: NaN | AO8: 0.000318266 | AP8: NaN | AQ8: 0.002411707 | AR8: 0.038672516 | AS8: 35.974976 | AT8: NaN | AU8: NaN | AV8: 4.9655704 | AW8: NaN | AX8: 0.010476299 | AY8: 0.79543293 | AZ8: 0.073594899 | BA8: NaN | BB8: NaN | BC8: 15.062454 | BD8: NaN | BE8: 0.014083968 | BF8: 32.522764 | BG8: 17.321572 | BH8: 0.034810067 | BI8: 17.733906 | BJ8: 0.013428581 | BK8: 1.0198043 | BL8: 1.3209644 | BM8: 1.3329441 | BN8: NaN | BO8: NaN | BP8: NaN | BQ8: 0.000444717 | BR8: NaN | BS8: 0.000960023 | BT8: 28.452951 | BU8: 30.001159 | BV8: NaN | BW8: NaN | BX8: NaN | BY8: 17.672857 | BZ8: NaN | CA8: 1.2745754 | CB8: 0.028797789 | CC8: NaN | CD8: 0.002012013 | CE8: 1.8366 | CF8: 125.00227 | CG8: 0.01214386 | CH8: 0.004246246 | CI8: NaN | CJ8: 0.000118497 | CK8: NaN | CL8: NaN | CM8: 0.006870641 | CN8: 42.531257 | CO8: NaN | CP8: NaN | CQ8: 13.904951 | CR8: NaN | CS8: 0.010704694 | CT8: 0.18732335 | CU8: 0.006585948 | CV8: NaN | CW8: NaN | CX8: 16.946735 | CY8: 0.002263208 | CZ8: 0.18553747 | DA8: 54.937263 | DB8: 29.4712 | DC8: 0.65463191 | DD8: 0.073514662 | DE8: 0.10799974 | DF8: 1.7629563 | DG8: 12.408713 | DH8: 48.519124 | DI8: 48.503649 | DJ8: 0.04895262 | DK8: 10.355873 | DL8: NaN | DM8: 0.036929839 | DN8: 3.5138082 | DO8: 670.80539 | DP8: 0.050510108 | DQ8: 0.0079495959 | DR8: 0.030446401 | DS8: 6.7858918 | DT8: 0.00042173185 | DU8: NaN | DV8: 1.3747416 | DW8: 0.12893995 | DX8: 0.0054441708 | DY8: 13.514253 | DZ8: =IFERROR(IF(BE8<J8,BE8*-1+J8,"NaN"),"NaN") -> 0.14790997 | EA8: =IFERROR(IF(BF8<K8,BF8*-1+K8,"NaN"),"NaN") -> 48.35386 | EB8: =IFERROR(IF(BG8<L8,BG8*-1+L8,"NaN"),"NaN") -> 280.30406 | EC8: =IFERROR(IF(BH8<M8,BH8*-1+M8,"NaN"),"NaN") -> 0.71170632 | ED8: =IFERROR(IF(BI8<N8,BI8*-1+N8,"NaN"),"NaN") -> 378.47368 | EE8: =IFERROR(IF(BJ8<O8,BJ8*-1+O8,"NaN"),"NaN") -> 0.11007006 | EF8: =IFERROR(IF(BK8<P8,BK8*-1+P8,"NaN"),"NaN") -> NaN | EG8: =IFERROR(IF(BL8<R8,BL8*-1+R8,"NaN"),"NaN") -> 22.259537 | EH8: =IFERROR(IF(BM8<Y8,BM8*-1+Y8,"NaN"),"NaN") -> 37.699573 | EI8: =IFERROR(IF(BN8<Z8,BN8*-1+Z8,"NaN"),"NaN") -> NaN | EJ8: =IFERROR(IF(BO8<AD8,BO8*-1+AD8,"NaN"),"NaN") -> NaN | EK8: =IFERROR(IF(BP8<AF8,BP8*-1+AF8,"NaN"),"NaN") -> NaN | EL8: =IFERROR(IF(BQ8<AG8,BQ8*-1+AG8,"NaN"),"NaN") -> NaN | EM8: =IFERROR(IF(BR8<AI8,BR8*-1+AI8,"NaN"),"NaN") -> NaN | EN8: =IFERROR(IF(BS8<AJ8,BS8*-1+AJ8,"NaN"),"NaN") -> 3.5723105 | EO8: =IFERROR(IF(BT8<AK8,BT8*-1+AK8,"NaN"),"NaN") -> 941.32963 | EP8: =IFERROR(IF(BU8<AL8,BU8*-1+AL8,"NaN"),"NaN") -> NaN | EQ8: =IFERROR(IF(BV8<AM8,BV8*-1+AM8,"NaN"),"NaN") -> NaN | ER8: =IFERROR(IF(BW8<AP8,BW8*-1+AP8,"NaN"),"NaN") -> NaN | ES8: =IFERROR(IF(BX8<AS8,BX8*-1+AS8,"NaN"),"NaN") -> NaN | ET8: =IFERROR(IF(BY8<AU8,BY8*-1+AU8,"NaN"),"NaN") -> NaN | EU8: =IFERROR(IF(BZ8<AV8,BZ8*-1+AV8,"NaN"),"NaN") -> NaN | EV8: =IFERROR(IF(CA8<AY8,CA8*-1+AY8,"NaN"),"NaN") -> NaN | EW8: =IFERROR(IF(CB8<AZ8,CB8*-1+AZ8,"NaN"),"NaN") -> 0.04479711 | EX8: =IFERROR(IF(CC8<BB8,CC8*-1+BB8,"NaN"),"NaN") -> NaN | EY8: =IFERROR(IF(CD8<BC8,CD8*-1+BC8,"NaN"),"NaN") -> 15.060442
A9: 18871 | B9: 3S | C9: 3 | D9: S | E9: -3776.1818 | F9: -67.0041 | G9: -100.035 | H9: 527.7803 | I9: 931.81818 | J9: 0.086816119 | K9: 1.0414451 | L9: 139.17947 | M9: 0.36010869 | N9: 185.23796 | O9: 0.12397802 | P9: NaN | Q9: 22.228759 | R9: 19.782011 | S9: NaN | T9: NaN | U9: NaN | V9: 0.02230935 | W9: NaN | X9: 0.009413514 | Y9: 24.650541 | Z9: 27.580528 | AA9: NaN | AB9: NaN | AC9: NaN | AD9: 176.04895 | AE9: NaN | AF9: 11.013368 | AG9: NaN | AH9: 0.00094386 | AI9: 0.013091437 | AJ9: 0.47109589 | AK9: 726.28555 | AL9: 0.011229414 | AM9: 0.023915485 | AN9: NaN | AO9: 9.28561e-05 | AP9: NaN | AQ9: NaN | AR9: 0.010265739 | AS9: 15.06813 | AT9: NaN | AU9: NaN | AV9: 4.4043748 | AW9: NaN | AX9: NaN | AY9: 0.2257122 | AZ9: 0.044984061 | BA9: NaN | BB9: NaN | BC9: 9.7332203 | BD9: NaN | BE9: 0.002324284 | BF9: 27.980916 | BG9: 10.506416 | BH9: 0.017553566 | BI9: 10.679385 | BJ9: 0.001227322 | BK9: 0.45966424 | BL9: 1.0015557 | BM9: 0.99455634 | BN9: NaN | BO9: NaN | BP9: NaN | BQ9: 0.000206391 | BR9: NaN | BS9: NaN | BT9: 3.4709644 | BU9: 3.5750007 | BV9: NaN | BW9: NaN | BX9: NaN | BY9: 10.641596 | BZ9: NaN | CA9: 0.65210677 | CB9: 0.024281067 | CC9: NaN | CD9: 0.000521275 | CE9: NaN | CF9: 29.923423 | CG9: 0.005852856 | CH9: 0.002061523 | CI9: NaN | CJ9: 6.56735e-05 | CK9: NaN | CL9: NaN | CM9: 0.006021339 | CN9: 17.935589 | CO9: NaN | CP9: NaN | CQ9: 1.5125939 | CR9: NaN | CS9: 0.005219104 | CT9: 0.053262319 | CU9: 0.002771841 | CV9: NaN | CW9: NaN | CX9: 2.4516738 | CY9: NaN | CZ9: 0.12651395 | DA9: 35.074946 | DB9: 28.842234 | DC9: 0.36556337 | DD9: 0.076859512 | DE9: 0.11421345 | DF9: NaN | DG9: 13.827107 | DH9: 23.856117 | DI9: 24.70458 | DJ9: 0.051989283 | DK9: 12.427411 | DL9: NaN | DM9: 0.036505629 | DN9: 2.0024008 | DO9: 507.01355 | DP9: 0.0069187143 | DQ9: 0.0089007157 | DR9: 0.011884101 | DS9: NaN | DT9: 0.00050601446 | DU9: NaN | DV9: 0.56107036 | DW9: 0.11431528 | DX9: 0.0048654499 | DY9: 7.0169213 | DZ9: =IFERROR(IF(BE9<J9,BE9*-1+J9,"NaN"),"NaN") -> 0.084491835 | EA9: =IFERROR(IF(BF9<K9,BF9*-1+K9,"NaN"),"NaN") -> NaN | EB9: =IFERROR(IF(BG9<L9,BG9*-1+L9,"NaN"),"NaN") -> 128.67306 | EC9: =IFERROR(IF(BH9<M9,BH9*-1+M9,"NaN"),"NaN") -> 0.34255512 | ED9: =IFERROR(IF(BI9<N9,BI9*-1+N9,"NaN"),"NaN") -> 174.55857 | EE9: =IFERROR(IF(BJ9<O9,BJ9*-1+O9,"NaN"),"NaN") -> 0.1227507 | EF9: =IFERROR(IF(BK9<P9,BK9*-1+P9,"NaN"),"NaN") -> NaN | EG9: =IFERROR(IF(BL9<R9,BL9*-1+R9,"NaN"),"NaN") -> 18.780455 | EH9: =IFERROR(IF(BM9<Y9,BM9*-1+Y9,"NaN"),"NaN") -> 23.655985 | EI9: =IFERROR(IF(BN9<Z9,BN9*-1+Z9,"NaN"),"NaN") -> NaN | EJ9: =IFERROR(IF(BO9<AD9,BO9*-1+AD9,"NaN"),"NaN") -> NaN | EK9: =IFERROR(IF(BP9<AF9,BP9*-1+AF9,"NaN"),"NaN") -> NaN | EL9: =IFERROR(IF(BQ9<AG9,BQ9*-1+AG9,"NaN"),"NaN") -> NaN | EM9: =IFERROR(IF(BR9<AI9,BR9*-1+AI9,"NaN"),"NaN") -> NaN | EN9: =IFERROR(IF(BS9<AJ9,BS9*-1+AJ9,"NaN"),"NaN") -> NaN | EO9: =IFERROR(IF(BT9<AK9,BT9*-1+AK9,"NaN"),"NaN") -> 722.81459 | EP9: =IFERROR(IF(BU9<AL9,BU9*-1+AL9,"NaN"),"NaN") -> NaN | EQ9: =IFERROR(IF(BV9<AM9,BV9*-1+AM9,"NaN"),"NaN") -> NaN | ER9: =IFERROR(IF(BW9<AP9,BW9*-1+AP9,"NaN"),"NaN") -> NaN | ES9: =IFERROR(IF(BX9<AS9,BX9*-1+AS9,"NaN"),"NaN") -> NaN | ET9: =IFERROR(IF(BY9<AU9,BY9*-1+AU9,"NaN"),"NaN") -> NaN | EU9: =IFERROR(IF(BZ9<AV9,BZ9*-1+AV9,"NaN"),"NaN") -> NaN | EV9: =IFERROR(IF(CA9<AY9,CA9*-1+AY9,"NaN"),"NaN") -> NaN | EW9: =IFERROR(IF(CB9<AZ9,CB9*-1+AZ9,"NaN"),"NaN") -> 0.020702994 | EX9: =IFERROR(IF(CC9<BB9,CC9*-1+BB9,"NaN"),"NaN") -> NaN | EY9: =IFERROR(IF(CD9<BC9,CD9*-1+BC9,"NaN"),"NaN") -> 9.7326991
A10: 18930 | B10: 3D | C10: 3 | D10: D | E10: -2977.33 | F10: -67.0041 | G10: -100.035 | H10: 527.7803 | I10: 1730.67 | J10: 0.067364007 | K10: 68.999432 | L10: 110.74491 | M10: 0.18080983 | N10: 145.57622 | O10: 0.20755867 | P10: 4.125055 | Q10: 27.143283 | R10: 24.697306 | S10: NaN | T10: NaN | U10: NaN | V10: 0.013500055 | W10: NaN | X10: 0.003329927 | Y10: 40.557004 | Z10: 43.353976 | AA10: NaN | AB10: NaN | AC10: 0.000383981 | AD10: 138.89823 | AE10: NaN | AF10: 32.86918 | AG10: NaN | AH10: 0.002478506 | AI10: 0.018132688 | AJ10: 0.87251356 | AK10: 687.64046 | AL10: 0.13245456 | AM10: 0.027536781 | AN10: NaN | AO10: NaN | AP10: NaN | AQ10: NaN | AR10: NaN | AS10: NaN | AT10: NaN | AU10: NaN | AV10: 7.5064994 | AW10: NaN | AX10: NaN | AY10: 0.3808594 | AZ10: 0.032001668 | BA10: NaN | BB10: NaN | BC10: 14.315612 | BD10: 0.074433822 | BE10: 0.001894067 | BF10: 520.8887 | BG10: 11.400995 | BH10: 0.008071992 | BI10: 12.65193 | BJ10: 0.028606511 | BK10: 3.560851 | BL10: 1.6420611 | BM10: 1.5913347 | BN10: NaN | BO10: NaN | BP10: NaN | BQ10: NaN | BR10: NaN | BS10: 0.00020634 | BT10: 18.703221 | BU10: 19.370871 | BV10: NaN | BW10: NaN | BX10: NaN | BY10: 12.419005 | BZ10: 8.45978e-05 | CA10: 4.4770409 | CB10: NaN | CC10: 0.000355844 | CD10: 0.002261221 | CE10: NaN | CF10: 22.824995 | CG10: 0.034914417 | CH10: 0.004090859 | CI10: NaN | CJ10: NaN | CK10: NaN | CL10: NaN | CM10: 0.00439277 | CN10: NaN | CO10: NaN | CP10: NaN | CQ10: 3.9437013 | CR10: NaN | CS10: 0.002579835 | CT10: 0.09417008 | CU10: 0.004590652 | CV10: NaN | CW10: NaN | CX10: 5.4097182 | CY10: NaN | CZ10: 0.0099846423 | DA10: 15.454269 | DB10: 0.044432628 | DC10: 0.0088061437 | DD10: 0.00030361637 | DE10: NaN | DF10: NaN | DG10: 2.0710191 | DH10: NaN | DI10: NaN | DJ10: NaN | DK10: NaN | DL10: NaN | DM10: NaN | DN10: 0.0611028 | DO10: NaN | DP10: NaN | DQ10: NaN | DR10: NaN | DS10: NaN | DT10: NaN | DU10: NaN | DV10: NaN | DW10: NaN | DX10: NaN | DY10: NaN | DZ10: =IFERROR(IF(BE10<J10,BE10*-1+J10,"NaN"),"NaN") -> 0.06546994 | EA10: =IFERROR(IF(BF10<K10,BF10*-1+K10,"NaN"),"NaN") -> NaN | EB10: =IFERROR(IF(BG10<L10,BG10*-1+L10,"NaN"),"NaN") -> 99.343916 | EC10: =IFERROR(IF(BH10<M10,BH10*-1+M10,"NaN"),"NaN") -> 0.17273784 | ED10: =IFERROR(IF(BI10<N10,BI10*-1+N10,"NaN"),"NaN") -> 132.92429 | EE10: =IFERROR(IF(BJ10<O10,BJ10*-1+O10,"NaN"),"NaN") -> 0.17895216 | EF10: =IFERROR(IF(BK10<P10,BK10*-1+P10,"NaN"),"NaN") -> 0.56420396 | EG10: =IFERROR(IF(BL10<R10,BL10*-1+R10,"NaN"),"NaN") -> 23.055245 | EH10: =IFERROR(IF(BM10<Y10,BM10*-1+Y10,"NaN"),"NaN") -> 38.965669 | EI10: =IFERROR(IF(BN10<Z10,BN10*-1+Z10,"NaN"),"NaN") -> NaN | EJ10: =IFERROR(IF(BO10<AD10,BO10*-1+AD10,"NaN"),"NaN") -> NaN | EK10: =IFERROR(IF(BP10<AF10,BP10*-1+AF10,"NaN"),"NaN") -> NaN | EL10: =IFERROR(IF(BQ10<AG10,BQ10*-1+AG10,"NaN"),"NaN") -> NaN | EM10: =IFERROR(IF(BR10<AI10,BR10*-1+AI10,"NaN"),"NaN") -> NaN | EN10: =IFERROR(IF(BS10<AJ10,BS10*-1+AJ10,"NaN"),"NaN") -> 0.87230722 | EO10: =IFERROR(IF(BT10<AK10,BT10*-1+AK10,"NaN"),"NaN") -> 668.93723 | EP10: =IFERROR(IF(BU10<AL10,BU10*-1+AL10,"NaN"),"NaN") -> NaN | EQ10: =IFERROR(IF(BV10<AM10,BV10*-1+AM10,"NaN"),"NaN") -> NaN | ER10: =IFERROR(IF(BW10<AP10,BW10*-1+AP10,"NaN"),"NaN") -> NaN | ES10: =IFERROR(IF(BX10<AS10,BX10*-1+AS10,"NaN"),"NaN") -> NaN | ET10: =IFERROR(IF(BY10<AU10,BY10*-1+AU10,"NaN"),"NaN") -> NaN | EU10: =IFERROR(IF(BZ10<AV10,BZ10*-1+AV10,"NaN"),"NaN") -> 7.5064148 | EV10: =IFERROR(IF(CA10<AY10,CA10*-1+AY10,"NaN"),"NaN") -> NaN | EW10: =IFERROR(IF(CB10<AZ10,CB10*-1+AZ10,"NaN"),"NaN") -> NaN | EX10: =IFERROR(IF(CC10<BB10,CC10*-1+BB10,"NaN"),"NaN") -> NaN | EY10: =IFERROR(IF(CD10<BC10,CD10*-1+BC10,"NaN"),"NaN") -> 14.313351
A11: 18931 | B11: 3D | C11: 3 | D11: D | E11: -2256.21 | F11: -67.0041 | G11: -100.035 | H11: 527.7803 | I11: 2451.79 | J11: 0.055731673 | K11: 33.013254 | L11: 65.49264 | M11: 0.10911368 | N11: 86.949147 | O11: 0.24016339 | P11: 0.39106078 | Q11: 21.488928 | R11: 19.604171 | S11: NaN | T11: NaN | U11: NaN | V11: 0.018977929 | W11: NaN | X11: 0.009843399 | Y11: 45.596635 | Z11: 48.521792 | AA11: NaN | AB11: NaN | AC11: 0.000840688 | AD11: 82.346231 | AE11: NaN | AF11: 61.536128 | AG11: NaN | AH11: 0.004387792 | AI11: 0.022579496 | AJ11: 0.29740798 | AK11: 586.05045 | AL11: 0.15507977 | AM11: 0.031443294 | AN11: NaN | AO11: 0.000230504 | AP11: NaN | AQ11: 0.003228429 | AR11: 0.049168207 | AS11: 188.79126 | AT11: NaN | AU11: NaN | AV11: 13.822923 | AW11: NaN | AX11: 0.003845735 | AY11: 0.23362047 | AZ11: 0.030965367 | BA11: NaN | BB11: NaN | BC11: 13.767233 | BD11: NaN | BE11: 0.001963639 | BF11: 250.80475 | BG11: 9.6382024 | BH11: 0.012529844 | BI11: 10.030616 | BJ11: 0.042250881 | BK11: 1.9464009 | BL11: 1.8445145 | BM11: 1.898889 | BN11: NaN | BO11: NaN | BP11: NaN | BQ11: NaN | BR11: NaN | BS11: 0.000361996 | BT11: 18.651603 | BU11: 18.807828 | BV11: NaN | BW11: NaN | BX11: NaN | BY11: 9.9345821 | BZ11: NaN | CA11: 11.704068 | CB11: 0.003031398 | CC11: 0.000785139 | CD11: 0.004444019 | CE11: NaN | CF11: 35.98738 | CG11: 0.031284675 | CH11: 0.0056431 | CI11: NaN | CJ11: NaN | CK11: NaN | CL11: NaN | CM11: 0.005938096 | CN11: 0.15346133 | CO11: NaN | CP11: NaN | CQ11: 3.0439288 | CR11: NaN | CS11: 0.004465736 | CT11: 0.13498055 | CU11: 0.005968306 | CV11: NaN | CW11: NaN | CX11: 2.0215175 | CY11: NaN | CZ11: 0.038248008 | DA11: 41.791215 | DB11: 10.087717 | DC11: 0.10429726 | DD11: 0.15738726 | DE11: 0.20816681 | DF11: 1.6393462 | DG11: 11.165313 | DH11: 87.739546 | DI11: 87.97648 | DJ11: 0.066727967 | DK11: 59.488312 | DL11: 0.53551541 | DM11: 0.051587869 | DN11: 1.0440485 | DO11: 427.84325 | DP11: 0.10650916 | DQ11: 0.012919443 | DR11: 0.016129058 | DS11: 143.71515 | DT11: 0.0013015003 | DU11: 0.14019032 | DV11: 1.0659745 | DW11: 0.095689964 | DX11: 0.0039501173 | DY11: 4.7999406 | DZ11: =IFERROR(IF(BE11<J11,BE11*-1+J11,"NaN"),"NaN") -> 0.053768034 | EA11: =IFERROR(IF(BF11<K11,BF11*-1+K11,"NaN"),"NaN") -> NaN | EB11: =IFERROR(IF(BG11<L11,BG11*-1+L11,"NaN"),"NaN") -> 55.854438 | EC11: =IFERROR(IF(BH11<M11,BH11*-1+M11,"NaN"),"NaN") -> 0.09658384 | ED11: =IFERROR(IF(BI11<N11,BI11*-1+N11,"NaN"),"NaN") -> 76.91853 | EE11: =IFERROR(IF(BJ11<O11,BJ11*-1+O11,"NaN"),"NaN") -> 0.19791251 | EF11: =IFERROR(IF(BK11<P11,BK11*-1+P11,"NaN"),"NaN") -> NaN | EG11: =IFERROR(IF(BL11<R11,BL11*-1+R11,"NaN"),"NaN") -> 17.759657 | EH11: =IFERROR(IF(BM11<Y11,BM11*-1+Y11,"NaN"),"NaN") -> 43.697746 | EI11: =IFERROR(IF(BN11<Z11,BN11*-1+Z11,"NaN"),"NaN") -> NaN | EJ11: =IFERROR(IF(BO11<AD11,BO11*-1+AD11,"NaN"),"NaN") -> NaN | EK11: =IFERROR(IF(BP11<AF11,BP11*-1+AF11,"NaN"),"NaN") -> NaN | EL11: =IFERROR(IF(BQ11<AG11,BQ11*-1+AG11,"NaN"),"NaN") -> NaN | EM11: =IFERROR(IF(BR11<AI11,BR11*-1+AI11,"NaN"),"NaN") -> NaN | EN11: =IFERROR(IF(BS11<AJ11,BS11*-1+AJ11,"NaN"),"NaN") -> 0.29704599 | EO11: =IFERROR(IF(BT11<AK11,BT11*-1+AK11,"NaN"),"NaN") -> 567.39884 | EP11: =IFERROR(IF(BU11<AL11,BU11*-1+AL11,"NaN"),"NaN") -> NaN | EQ11: =IFERROR(IF(BV11<AM11,BV11*-1+AM11,"NaN"),"NaN") -> NaN | ER11: =IFERROR(IF(BW11<AP11,BW11*-1+AP11,"NaN"),"NaN") -> NaN | ES11: =IFERROR(IF(BX11<AS11,BX11*-1+AS11,"NaN"),"NaN") -> NaN | ET11: =IFERROR(IF(BY11<AU11,BY11*-1+AU11,"NaN"),"NaN") -> NaN | EU11: =IFERROR(IF(BZ11<AV11,BZ11*-1+AV11,"NaN"),"NaN") -> NaN | EV11: =IFERROR(IF(CA11<AY11,CA11*-1+AY11,"NaN"),"NaN") -> NaN | EW11: =IFERROR(IF(CB11<AZ11,CB11*-1+AZ11,"NaN"),"NaN") -> 0.027933969 | EX11: =IFERROR(IF(CC11<BB11,CC11*-1+BB11,"NaN"),"NaN") -> NaN | EY11: =IFERROR(IF(CD11<BC11,CD11*-1+BC11,"NaN"),"NaN") -> 13.762788
A12: 18932 | B12: 3D | C12: 3 | D12: D | E12: -1636.05 | F12: -67.0041 | G12: -100.035 | H12: 527.7803 | I12: 3071.95 | J12: 0.035543377 | K12: 5.0633062 | L12: 46.19907 | M12: 0.11371255 | N12: 60.350158 | O12: 0.2733232 | P12: NaN | Q12: 20.449243 | R12: 18.768836 | S12: NaN | T12: NaN | U12: NaN | V12: 0.020092538 | W12: NaN | X12: 0.008237325 | Y12: 25.469669 | Z12: 24.34321 | AA12: NaN | AB12: NaN | AC12: NaN | AD12: 56.884756 | AE12: NaN | AF12: 71.395542 | AG12: NaN | AH12: 0.00156571 | AI12: 0.012065822 | AJ12: NaN | AK12: 559.75981 | AL12: 0.088583928 | AM12: 0.018918786 | AN12: NaN | AO12: 0.000648377 | AP12: NaN | AQ12: 0.000349704 | AR12: 0.048398351 | AS12: 129.0367 | AT12: NaN | AU12: NaN | AV12: 8.2484812 | AW12: NaN | AX12: NaN | AY12: 0.12756633 | AZ12: 0.013343468 | BA12: NaN | BB12: NaN | BC12: 4.2515845 | BD12: NaN | BE12: NaN | BF12: 45.772407 | BG12: 10.393157 | BH12: 0.008512784 | BI12: 10.418767 | BJ12: 0.069524258 | BK12: 1.3825621 | BL12: 2.0182991 | BM12: 2.050949 | BN12: NaN | BO12: NaN | BP12: NaN | BQ12: 0.000231785 | BR12: NaN | BS12: 0.001744505 | BT12: 25.913154 | BU12: 26.898074 | BV12: NaN | BW12: NaN | BX12: NaN | BY12: 10.487747 | BZ12: 2.2291e-06 | CA12: 19.785921 | CB12: NaN | CC12: 0.001752158 | CD12: 0.008582949 | CE12: NaN | CF12: 28.549832 | CG12: 0.04458528 | CH12: 0.009827886 | CI12: NaN | CJ12: NaN | CK12: NaN | CL12: 0.00049498 | CM12: 0.011234529 | CN12: 2.7552013 | CO12: NaN | CP12: NaN | CQ12: 2.9407142 | CR12: NaN | CS12: 0.002474047 | CT12: 0.15676645 | CU12: 0.008205527 | CV12: NaN | CW12: NaN | CX12: 1.6221956 | CY12: NaN | CZ12: 0.041128429 | DA12: 62.572962 | DB12: 10.877631 | DC12: 0.13698293 | DD12: 0.23705542 | DE12: 0.3588277 | DF12: 1.7250752 | DG12: 15.520847 | DH12: 142.28484 | DI12: 141.41531 | DJ12: 0.093361084 | DK12: 104.10252 | DL12: 0.061906761 | DM12: 0.088115006 | DN12: 1.233311 | DO12: 467.61244 | DP12: 0.10509103 | DQ12: 0.021510275 | DR12: 0.033289169 | DS12: 115.71672 | DT12: 0.0029171472 | DU12: 0.45098606 | DV12: 1.5725816 | DW12: 0.14299103 | DX12: 0.0069828822 | DY12: 0.98766758 | DZ12: =IFERROR(IF(BE12<J12,BE12*-1+J12,"NaN"),"NaN") -> NaN | EA12: =IFERROR(IF(BF12<K12,BF12*-1+K12,"NaN"),"NaN") -> NaN | EB12: =IFERROR(IF(BG12<L12,BG12*-1+L12,"NaN"),"NaN") -> 35.805913 | EC12: =IFERROR(IF(BH12<M12,BH12*-1+M12,"NaN"),"NaN") -> 0.10519977 | ED12: =IFERROR(IF(BI12<N12,BI12*-1+N12,"NaN"),"NaN") -> 49.931392 | EE12: =IFERROR(IF(BJ12<O12,BJ12*-1+O12,"NaN"),"NaN") -> 0.20379894 | EF12: =IFERROR(IF(BK12<P12,BK12*-1+P12,"NaN"),"NaN") -> NaN | EG12: =IFERROR(IF(BL12<R12,BL12*-1+R12,"NaN"),"NaN") -> 16.750537 | EH12: =IFERROR(IF(BM12<Y12,BM12*-1+Y12,"NaN"),"NaN") -> 23.41872 | EI12: =IFERROR(IF(BN12<Z12,BN12*-1+Z12,"NaN"),"NaN") -> NaN | EJ12: =IFERROR(IF(BO12<AD12,BO12*-1+AD12,"NaN"),"NaN") -> NaN | EK12: =IFERROR(IF(BP12<AF12,BP12*-1+AF12,"NaN"),"NaN") -> NaN | EL12: =IFERROR(IF(BQ12<AG12,BQ12*-1+AG12,"NaN"),"NaN") -> NaN | EM12: =IFERROR(IF(BR12<AI12,BR12*-1+AI12,"NaN"),"NaN") -> NaN | EN12: =IFERROR(IF(BS12<AJ12,BS12*-1+AJ12,"NaN"),"NaN") -> NaN | EO12: =IFERROR(IF(BT12<AK12,BT12*-1+AK12,"NaN"),"NaN") -> 533.84666 | EP12: =IFERROR(IF(BU12<AL12,BU12*-1+AL12,"NaN"),"NaN") -> NaN | EQ12: =IFERROR(IF(BV12<AM12,BV12*-1+AM12,"NaN"),"NaN") -> NaN | ER12: =IFERROR(IF(BW12<AP12,BW12*-1+AP12,"NaN"),"NaN") -> NaN | ES12: =IFERROR(IF(BX12<AS12,BX12*-1+AS12,"NaN"),"NaN") -> NaN | ET12: =IFERROR(IF(BY12<AU12,BY12*-1+AU12,"NaN"),"NaN") -> NaN | EU12: =IFERROR(IF(BZ12<AV12,BZ12*-1+AV12,"NaN"),"NaN") -> 8.248479 | EV12: =IFERROR(IF(CA12<AY12,CA12*-1+AY12,"NaN"),"NaN") -> NaN | EW12: =IFERROR(IF(CB12<AZ12,CB12*-1+AZ12,"NaN"),"NaN") -> NaN | EX12: =IFERROR(IF(CC12<BB12,CC12*-1+BB12,"NaN"),"NaN") -> NaN | EY12: =IFERROR(IF(CD12<BC12,CD12*-1+BC12,"NaN"),"NaN") -> 4.2430016
A13: 18933 | B13: 3D | C13: 3 | D13: D | E13: -1054.36 | F13: -67.0041 | G13: -100.035 | H13: 527.7803 | I13: 3653.64 | J13: 0.028653292 | K13: 427.9395 | L13: 58.707017 | M13: 0.1042762 | N13: 77.299554 | O13: 0.41240412 | P13: NaN | Q13: 20.756524 | R13: 18.427293 | S13: NaN | T13: 0.000231574 | U13: 0.002712159 | V13: 0.023398924 | W13: NaN | X13: 0.018317804 | Y13: 212.41205 | Z13: 213.3742 | AA13: NaN | AB13: 0.001086501 | AC13: 0.006263626 | AD13: 73.412656 | AE13: 0.00129375 | AF13: 70.362115 | AG13: NaN | AH13: 0.011932334 | AI13: 0.051549293 | AJ13: 0.33693983 | AK13: 477.62309 | AL13: 0.16461807 | AM13: 0.055601392 | AN13: 0.82290841 | AO13: 0.000806113 | AP13: NaN | AQ13: 0.007766446 | AR13: 0.091329164 | AS13: 197.42417 | AT13: NaN | AU13: NaN | AV13: 31.718984 | AW13: 0.001515698 | AX13: 0.017016508 | AY13: 0.83803432 | AZ13: 0.062381648 | BA13: NaN | BB13: 0.000303288 | BC13: 4.4896455 | BD13: NaN | BE13: 0.001254703 | BF13: 140.05092 | BG13: 11.448541 | BH13: 0.052835107 | BI13: 11.553824 | BJ13: 0.089438649 | BK13: 1.5422646 | BL13: 2.4902198 | BM13: 2.4492932 | BN13: NaN | BO13: NaN | BP13: NaN | BQ13: 0.000739633 | BR13: NaN | BS13: 0.002732642 | BT13: 68.463226 | BU13: 67.12159 | BV13: NaN | BW13: NaN | BX13: 0.000667903 | BY13: 11.583153 | BZ13: 0.001253576 | CA13: 18.32813 | CB13: 0.022933929 | CC13: 0.003135824 | CD13: 0.012381926 | CE13: NaN | CF13: 41.070443 | CG13: 0.033501986 | CH13: 0.013368822 | CI13: 0.014980495 | CJ13: 0.000143369 | CK13: NaN | CL13: 0.001624158 | CM13: 0.017654718 | CN13: 2.5953289 | CO13: NaN | CP13: 0.000228618 | CQ13: 11.345957 | CR13: 0.000399267 | CS13: 0.003728604 | CT13: 0.26148962 | CU13: 0.079842104 | CV13: 0.000360249 | CW13: 0.000597035 | CX13: 0.66633104 | CY13: 0.089414703 | CZ13: 0.038181402 | DA13: 204.31628 | DB13: 8.6703898 | DC13: 0.10742931 | DD13: 0.25168107 | DE13: 0.38777031 | DF13: NaN | DG13: 14.321736 | DH13: 144.05305 | DI13: 143.63303 | DJ13: 0.087193632 | DK13: 78.779566 | DL13: 0.20547681 | DM13: 0.088719905 | DN13: 1.1281443 | DO13: 443.79898 | DP13: 0.11929171 | DQ13: 0.021992808 | DR13: 0.051841929 | DS13: 205.34358 | DT13: 0.0062220388 | DU13: 1.6953238 | DV13: 1.1613189 | DW13: 0.13355857 | DX13: 0.005866117 | DY13: 5.0152385 | DZ13: =IFERROR(IF(BE13<J13,BE13*-1+J13,"NaN"),"NaN") -> 0.027398589 | EA13: =IFERROR(IF(BF13<K13,BF13*-1+K13,"NaN"),"NaN") -> 287.88859 | EB13: =IFERROR(IF(BG13<L13,BG13*-1+L13,"NaN"),"NaN") -> 47.258477 | EC13: =IFERROR(IF(BH13<M13,BH13*-1+M13,"NaN"),"NaN") -> 0.051441097 | ED13: =IFERROR(IF(BI13<N13,BI13*-1+N13,"NaN"),"NaN") -> 65.74573 | EE13: =IFERROR(IF(BJ13<O13,BJ13*-1+O13,"NaN"),"NaN") -> 0.32296547 | EF13: =IFERROR(IF(BK13<P13,BK13*-1+P13,"NaN"),"NaN") -> NaN | EG13: =IFERROR(IF(BL13<R13,BL13*-1+R13,"NaN"),"NaN") -> 15.937073 | EH13: =IFERROR(IF(BM13<Y13,BM13*-1+Y13,"NaN"),"NaN") -> 209.96276 | EI13: =IFERROR(IF(BN13<Z13,BN13*-1+Z13,"NaN"),"NaN") -> NaN | EJ13: =IFERROR(IF(BO13<AD13,BO13*-1+AD13,"NaN"),"NaN") -> NaN | EK13: =IFERROR(IF(BP13<AF13,BP13*-1+AF13,"NaN"),"NaN") -> NaN | EL13: =IFERROR(IF(BQ13<AG13,BQ13*-1+AG13,"NaN"),"NaN") -> NaN | EM13: =IFERROR(IF(BR13<AI13,BR13*-1+AI13,"NaN"),"NaN") -> NaN | EN13: =IFERROR(IF(BS13<AJ13,BS13*-1+AJ13,"NaN"),"NaN") -> 0.33420719 | EO13: =IFERROR(IF(BT13<AK13,BT13*-1+AK13,"NaN"),"NaN") -> 409.15987 | EP13: =IFERROR(IF(BU13<AL13,BU13*-1+AL13,"NaN"),"NaN") -> NaN | EQ13: =IFERROR(IF(BV13<AM13,BV13*-1+AM13,"NaN"),"NaN") -> NaN | ER13: =IFERROR(IF(BW13<AP13,BW13*-1+AP13,"NaN"),"NaN") -> NaN | ES13: =IFERROR(IF(BX13<AS13,BX13*-1+AS13,"NaN"),"NaN") -> 197.4235 | ET13: =IFERROR(IF(BY13<AU13,BY13*-1+AU13,"NaN"),"NaN") -> NaN | EU13: =IFERROR(IF(BZ13<AV13,BZ13*-1+AV13,"NaN"),"NaN") -> 31.717731 | EV13: =IFERROR(IF(CA13<AY13,CA13*-1+AY13,"NaN"),"NaN") -> NaN | EW13: =IFERROR(IF(CB13<AZ13,CB13*-1+AZ13,"NaN"),"NaN") -> 0.039447719 | EX13: =IFERROR(IF(CC13<BB13,CC13*-1+BB13,"NaN"),"NaN") -> NaN | EY13: =IFERROR(IF(CD13<BC13,CD13*-1+BC13,"NaN"),"NaN") -> 4.4772635
A14: 18934 | B14: 3D | C14: 3 | D14: D | E14: -669.76 | F14: -67.0041 | G14: -100.035 | H14: 527.7803 | I14: 4038.24 | J14: 0.04022877 | K14: 1161.425 | L14: 78.058901 | M14: 0.12497838 | N14: 102.30555 | O14: 0.8286729 | P14: 1.7901191 | Q14: 25.248433 | R14: 22.641859 | S14: NaN | T14: 0.001016069 | U14: 0.002109848 | V14: 0.014237544 | W14: NaN | X14: 0.03878911 | Y14: 489.6867 | Z14: 505.35385 | AA14: NaN | AB14: NaN | AC14: 0.005004114 | AD14: 96.992873 | AE14: NaN | AF14: 102.72842 | AG14: NaN | AH14: 0.031444174 | AI14: 0.12182867 | AJ14: 1.87505 | AK14: 579.2349 | AL14: 0.31050443 | AM14: 0.13686275 | AN14: NaN | AO14: 0.001901931 | AP14: 0.091716355 | AQ14: 0.024527758 | AR14: 0.1778044 | AS14: 152.29928 | AT14: NaN | AU14: 0.003020844 | AV14: 73.130888 | AW14: 0.000229832 | AX14: 0.004022344 | AY14: 1.7569528 | AZ14: 0.11407271 | BA14: NaN | BB14: NaN | BC14: 18.611647 | BD14: 0.15536989 | BE14: 0.002377559 | BF14: 290.32632 | BG14: 8.6851255 | BH14: 0.020971341 | BI14: 8.7461987 | BJ14: 0.1024423 | BK14: 0.54716726 | BL14: 1.9342181 | BM14: 1.9314774 | BN14: NaN | BO14: NaN | BP14: NaN | BQ14: 0.000723567 | BR14: NaN | BS14: 0.003408932 | BT14: 107.19357 | BU14: 106.13443 | BV14: NaN | BW14: NaN | BX14: 0.000595975 | BY14: 8.7762127 | BZ14: 0.000429931 | CA14: 15.894827 | CB14: 0.017618179 | CC14: 0.003296301 | CD14: 0.01404658 | CE14: NaN | CF14: 28.966007 | CG14: 0.033376816 | CH14: 0.016019045 | CI14: 0.073672691 | CJ14: 4.24861e-05 | CK14: NaN | CL14: 0.001916279 | CM14: 0.019075631 | CN14: 27.752821 | CO14: NaN | CP14: 0.00031369 | CQ14: 11.791904 | CR14: NaN | CS14: 0.003281506 | CT14: 0.32466292 | CU14: 0.0186843 | CV14: NaN | CW14: 0.000243982 | CX14: 10.011946 | CY14: NaN | CZ14: 0.037577761 | DA14: 467.66056 | DB14: 9.6793005 | DC14: 0.14919153 | DD14: 0.34575766 | DE14: 0.63224402 | DF14: NaN | DG14: 15.97913 | DH14: 213.6814 | DI14: 212.53353 | DJ14: 0.11721389 | DK14: 96.984188 | DL14: 0.28168503 | DM14: 0.1196935 | DN14: 1.7897181 | DO14: 496.43023 | DP14: 0.16721751 | DQ14: 0.029953603 | DR14: 0.099428022 | DS14: 210.0192 | DT14: 0.01319377 | DU14: 3.6335467 | DV14: 1.2881977 | DW14: 0.15877477 | DX14: 0.0078479115 | DY14: 45.906668 | DZ14: =IFERROR(IF(BE14<J14,BE14*-1+J14,"NaN"),"NaN") -> 0.037851211 | EA14: =IFERROR(IF(BF14<K14,BF14*-1+K14,"NaN"),"NaN") -> 871.09871 | EB14: =IFERROR(IF(BG14<L14,BG14*-1+L14,"NaN"),"NaN") -> 69.373776 | EC14: =IFERROR(IF(BH14<M14,BH14*-1+M14,"NaN"),"NaN") -> 0.10400703 | ED14: =IFERROR(IF(BI14<N14,BI14*-1+N14,"NaN"),"NaN") -> 93.559351 | EE14: =IFERROR(IF(BJ14<O14,BJ14*-1+O14,"NaN"),"NaN") -> 0.7262306 | EF14: =IFERROR(IF(BK14<P14,BK14*-1+P14,"NaN"),"NaN") -> 1.2429519 | EG14: =IFERROR(IF(BL14<R14,BL14*-1+R14,"NaN"),"NaN") -> 20.707641 | EH14: =IFERROR(IF(BM14<Y14,BM14*-1+Y14,"NaN"),"NaN") -> 487.75522 | EI14: =IFERROR(IF(BN14<Z14,BN14*-1+Z14,"NaN"),"NaN") -> NaN | EJ14: =IFERROR(IF(BO14<AD14,BO14*-1+AD14,"NaN"),"NaN") -> NaN | EK14: =IFERROR(IF(BP14<AF14,BP14*-1+AF14,"NaN"),"NaN") -> NaN | EL14: =IFERROR(IF(BQ14<AG14,BQ14*-1+AG14,"NaN"),"NaN") -> NaN | EM14: =IFERROR(IF(BR14<AI14,BR14*-1+AI14,"NaN"),"NaN") -> NaN | EN14: =IFERROR(IF(BS14<AJ14,BS14*-1+AJ14,"NaN"),"NaN") -> 1.8716411 | EO14: =IFERROR(IF(BT14<AK14,BT14*-1+AK14,"NaN"),"NaN") -> 472.04133 | EP14: =IFERROR(IF(BU14<AL14,BU14*-1+AL14,"NaN"),"NaN") -> NaN | EQ14: =IFERROR(IF(BV14<AM14,BV14*-1+AM14,"NaN"),"NaN") -> NaN | ER14: =IFERROR(IF(BW14<AP14,BW14*-1+AP14,"NaN"),"NaN") -> NaN | ES14: =IFERROR(IF(BX14<AS14,BX14*-1+AS14,"NaN"),"NaN") -> 152.29869 | ET14: =IFERROR(IF(BY14<AU14,BY14*-1+AU14,"NaN"),"NaN") -> NaN | EU14: =IFERROR(IF(BZ14<AV14,BZ14*-1+AV14,"NaN"),"NaN") -> 73.130458 | EV14: =IFERROR(IF(CA14<AY14,CA14*-1+AY14,"NaN"),"NaN") -> NaN | EW14: =IFERROR(IF(CB14<AZ14,CB14*-1+AZ14,"NaN"),"NaN") -> 0.096454529 | EX14: =IFERROR(IF(CC14<BB14,CC14*-1+BB14,"NaN"),"NaN") -> NaN | EY14: =IFERROR(IF(CD14<BC14,CD14*-1+BC14,"NaN"),"NaN") -> 18.5976
A15: 18935 | B15: 3D | C15: 3 | D15: D | E15: -371.7 | F15: -67.0041 | G15: -100.035 | H15: 527.7803 | I15: 4336.3 | J15: 0.066638494 | K15: 2759.1699 | L15: 75.648594 | M15: 0.12678673 | N15: 99.781389 | O15: 1.1265943 | P15: 0.20327893 | Q15: 21.071497 | R15: 19.19758 | S15: 0.016702694 | T15: 0.019282212 | U15: 0.012768392 | V15: 0.030347982 | W15: 0.001046619 | X15: 0.04563088 | Y15: 921.02747 | Z15: 953.21726 | AA15: NaN | AB15: 0.005121284 | AC15: 0.024394089 | AD15: 94.60598 | AE15: 0.011142768 | AF15: 135.881 | AG15: NaN | AH15: 0.054224579 | AI15: 0.18382098 | AJ15: 2.2564486 | AK15: 578.98499 | AL15: 0.29467669 | AM15: 0.21647713 | AN15: NaN | AO15: 0.000292916 | AP15: 0.33666567 | AQ15: 0.032106607 | AR15: 0.20450048 | AS15: NaN | AT15: 0.017957632 | AU15: 0.017396415 | AV15: 119.51392 | AW15: 0.01006359 | AX15: NaN | AY15: 2.7242122 | AZ15: 0.21431145 | BA15: 0.013500769 | BB15: 0.01326875 | BC15: 8.3131839 | BD15: 0.55145023 | BE15: 0.00104799 | BF15: 564.90669 | BG15: 17.872148 | BH15: 0.011925027 | BI15: 17.893318 | BJ15: 0.26629142 | BK15: 5.9180038 | BL15: 2.9774854 | BM15: 2.9347716 | BN15: 0.000628735 | BO15: 0.002260356 | BP15: NaN | BQ15: 0.001596436 | BR15: NaN | BS15: 0.009657143 | BT15: 256.66049 | BU15: 255.71769 | BV15: NaN | BW15: 0.0001634 | BX15: 0.003800487 | BY15: 18.014337 | BZ15: 0.001786946 | CA15: 33.458785 | CB15: 0.21246621 | CC15: 0.012576358 | CD15: 0.044849344 | CE15: NaN | CF15: 45.252381 | CG15: 0.073670794 | CH15: 0.049252564 | CI15: 0.31578319 | CJ15: 3.51238e-05 | CK15: 0.048339514 | CL15: 0.007222321 | CM15: 0.051433664 | CN15: 9.3218072 | CO15: NaN | CP15: 0.002327834 | CQ15: 29.404436 | CR15: 0.001448118 | CS15: 0.00522474 | CT15: 0.77196719 | CU15: 0.048304029 | CV15: 0.001242447 | CW15: 0.002055653 | CX15: 2.295553 | CY15: 0.056923672 | CZ15: 0.030320426 | DA15: 746.74911 | DB15: 9.5326387 | DC15: 0.083287625 | DD15: 0.45381195 | DE15: 0.84920136 | DF15: 2.4031178 | DG15: 13.887807 | DH15: 303.81652 | DI15: 316.64928 | DJ15: 0.15621118 | DK15: 129.76177 | DL15: 0.22440782 | DM15: 0.15735248 | DN15: 2.2048425 | DO15: 432.12906 | DP15: 0.20590598 | DQ15: 0.038220669 | DR15: 0.13924051 | DS15: 109.1399 | DT15: 0.020819677 | DU15: 6.1671201 | DV15: 1.3642369 | DW15: 0.18717395 | DX15: 0.009033339 | DY15: 5.7768172 | DZ15: =IFERROR(IF(BE15<J15,BE15*-1+J15,"NaN"),"NaN") -> 0.065590504 | EA15: =IFERROR(IF(BF15<K15,BF15*-1+K15,"NaN"),"NaN") -> 2194.2632 | EB15: =IFERROR(IF(BG15<L15,BG15*-1+L15,"NaN"),"NaN") -> 57.776446 | EC15: =IFERROR(IF(BH15<M15,BH15*-1+M15,"NaN"),"NaN") -> 0.11486171 | ED15: =IFERROR(IF(BI15<N15,BI15*-1+N15,"NaN"),"NaN") -> 81.888071 | EE15: =IFERROR(IF(BJ15<O15,BJ15*-1+O15,"NaN"),"NaN") -> 0.86030289 | EF15: =IFERROR(IF(BK15<P15,BK15*-1+P15,"NaN"),"NaN") -> NaN | EG15: =IFERROR(IF(BL15<R15,BL15*-1+R15,"NaN"),"NaN") -> 16.220095 | EH15: =IFERROR(IF(BM15<Y15,BM15*-1+Y15,"NaN"),"NaN") -> 918.0927 | EI15: =IFERROR(IF(BN15<Z15,BN15*-1+Z15,"NaN"),"NaN") -> 953.21663 | EJ15: =IFERROR(IF(BO15<AD15,BO15*-1+AD15,"NaN"),"NaN") -> 94.60372 | EK15: =IFERROR(IF(BP15<AF15,BP15*-1+AF15,"NaN"),"NaN") -> NaN | EL15: =IFERROR(IF(BQ15<AG15,BQ15*-1+AG15,"NaN"),"NaN") -> NaN | EM15: =IFERROR(IF(BR15<AI15,BR15*-1+AI15,"NaN"),"NaN") -> NaN | EN15: =IFERROR(IF(BS15<AJ15,BS15*-1+AJ15,"NaN"),"NaN") -> 2.2467915 | EO15: =IFERROR(IF(BT15<AK15,BT15*-1+AK15,"NaN"),"NaN") -> 322.3245 | EP15: =IFERROR(IF(BU15<AL15,BU15*-1+AL15,"NaN"),"NaN") -> NaN | EQ15: =IFERROR(IF(BV15<AM15,BV15*-1+AM15,"NaN"),"NaN") -> NaN | ER15: =IFERROR(IF(BW15<AP15,BW15*-1+AP15,"NaN"),"NaN") -> 0.33650227 | ES15: =IFERROR(IF(BX15<AS15,BX15*-1+AS15,"NaN"),"NaN") -> NaN | ET15: =IFERROR(IF(BY15<AU15,BY15*-1+AU15,"NaN"),"NaN") -> NaN | EU15: =IFERROR(IF(BZ15<AV15,BZ15*-1+AV15,"NaN"),"NaN") -> 119.51213 | EV15: =IFERROR(IF(CA15<AY15,CA15*-1+AY15,"NaN"),"NaN") -> NaN | EW15: =IFERROR(IF(CB15<AZ15,CB15*-1+AZ15,"NaN"),"NaN") -> 0.001845239 | EX15: =IFERROR(IF(CC15<BB15,CC15*-1+BB15,"NaN"),"NaN") -> 0.000692392 | EY15: =IFERROR(IF(CD15<BC15,CD15*-1+BC15,"NaN"),"NaN") -> 8.2683345
A16: 18936 | B16: 3D | C16: 3 | D16: D | E16: -275.55 | F16: -67.0041 | G16: -100.035 | H16: 527.7803 | I16: 4432.45 | J16: 0.026890594 | K16: 3089.6568 | L16: 91.226334 | M16: 0.15798604 | N16: 119.8601 | O16: 1.5439951 | P16: 1.9415065 | Q16: 22.535755 | R16: 20.692234 | S16: 0.024196229 | T16: 0.023345387 | U16: 0.016740521 | V16: 0.035734341 | W16: 0.002814204 | X16: 0.060903838 | Y16: 1154.8648 | Z16: 1173.4453 | AA16: NaN | AB16: 0.00689706 | AC16: 0.028559898 | AD16: 113.75975 | AE16: 0.012281327 | AF16: 172.03198 | AG16: NaN | AH16: 0.065680889 | AI16: 0.23006165 | AJ16: 2.7065126 | AK16: 632.27715 | AL16: 0.40234306 | AM16: 0.27055361 | AN16: 1.5860468 | AO16: 0.001595969 | AP16: 0.36861961 | AQ16: 0.041493 | AR16: 0.2742108 | AS16: 148.26351 | AT16: 0.024023492 | AU16: 0.024401562 | AV16: 165.35228 | AW16: 0.013554316 | AX16: 0.011408865 | AY16: 3.6489897 | AZ16: 0.24926968 | BA16: 0.014797796 | BB16: 0.016162773 | BC16: 10.76107 | BD16: 0.82504977 | BE16: NaN | BF16: 497.38228 | BG16: 12.973655 | BH16: 0.010462834 | BI16: 12.961929 | BJ16: 0.19337801 | BK16: 2.4582621 | BL16: 2.1508028 | BM16: 2.2011899 | BN16: NaN | BO16: 0.00013325 | BP16: NaN | BQ16: 0.001120926 | BR16: NaN | BS16: 0.007314996 | BT16: 163.7254 | BU16: 165.3988 | BV16: NaN | BW16: NaN | BX16: 0.002454985 | BY16: 12.972292 | BZ16: 0.001102358 | CA16: 27.054782 | CB16: 0.015964322 | CC16: 0.009053439 | CD16: 0.033630031 | CE16: NaN | CF16: 29.661759 | CG16: 0.073066588 | CH16: 0.036870106 | CI16: 0.25392942 | CJ16: 0.000107124 | CK16: 0.024484838 | CL16: 0.006073903 | CM16: 0.040158124 | CN16: NaN | CO16: NaN | CP16: 0.000715535 | CQ16: 21.053789 | CR16: 0.000732179 | CS16: 0.003565203 | CT16: 0.53944454 | CU16: 0.03381982 | CV16: 0.000469974 | CW16: 0.001045725 | CX16: 2.3920144 | CY16: 0.002714037 | CZ16: 0.041397545 | DA16: 844.31866 | DB16: 14.62524 | DC16: 0.087530392 | DD16: 0.55305747 | DE16: 0.91719928 | DF16: 0.32708679 | DG16: 13.63492 | DH16: 347.87817 | DI16: 357.72697 | DJ16: 0.17738038 | DK16: 136.61904 | DL16: NaN | DM16: 0.18393618 | DN16: 2.162322 | DO16: 327.1032 | DP16: 0.3555318 | DQ16: 0.047107476 | DR16: 0.14079161 | DS16: 5.77263 | DT16: 0.02407679 | DU16: 5.9691572 | DV16: 1.2315355 | DW16: 0.21537135 | DX16: 0.010338756 | DY16: 8.8248234 | DZ16: =IFERROR(IF(BE16<J16,BE16*-1+J16,"NaN"),"NaN") -> NaN | EA16: =IFERROR(IF(BF16<K16,BF16*-1+K16,"NaN"),"NaN") -> 2592.2745 | EB16: =IFERROR(IF(BG16<L16,BG16*-1+L16,"NaN"),"NaN") -> 78.25268 | EC16: =IFERROR(IF(BH16<M16,BH16*-1+M16,"NaN"),"NaN") -> 0.14752321 | ED16: =IFERROR(IF(BI16<N16,BI16*-1+N16,"NaN"),"NaN") -> 106.89817 | EE16: =IFERROR(IF(BJ16<O16,BJ16*-1+O16,"NaN"),"NaN") -> 1.3506171 | EF16: =IFERROR(IF(BK16<P16,BK16*-1+P16,"NaN"),"NaN") -> NaN | EG16: =IFERROR(IF(BL16<R16,BL16*-1+R16,"NaN"),"NaN") -> 18.541431 | EH16: =IFERROR(IF(BM16<Y16,BM16*-1+Y16,"NaN"),"NaN") -> 1152.6636 | EI16: =IFERROR(IF(BN16<Z16,BN16*-1+Z16,"NaN"),"NaN") -> NaN | EJ16: =IFERROR(IF(BO16<AD16,BO16*-1+AD16,"NaN"),"NaN") -> 113.75962 | EK16: =IFERROR(IF(BP16<AF16,BP16*-1+AF16,"NaN"),"NaN") -> NaN | EL16: =IFERROR(IF(BQ16<AG16,BQ16*-1+AG16,"NaN"),"NaN") -> NaN | EM16: =IFERROR(IF(BR16<AI16,BR16*-1+AI16,"NaN"),"NaN") -> NaN | EN16: =IFERROR(IF(BS16<AJ16,BS16*-1+AJ16,"NaN"),"NaN") -> 2.6991976 | EO16: =IFERROR(IF(BT16<AK16,BT16*-1+AK16,"NaN"),"NaN") -> 468.55175 | EP16: =IFERROR(IF(BU16<AL16,BU16*-1+AL16,"NaN"),"NaN") -> NaN | EQ16: =IFERROR(IF(BV16<AM16,BV16*-1+AM16,"NaN"),"NaN") -> NaN | ER16: =IFERROR(IF(BW16<AP16,BW16*-1+AP16,"NaN"),"NaN") -> NaN | ES16: =IFERROR(IF(BX16<AS16,BX16*-1+AS16,"NaN"),"NaN") -> 148.26105 | ET16: =IFERROR(IF(BY16<AU16,BY16*-1+AU16,"NaN"),"NaN") -> NaN | EU16: =IFERROR(IF(BZ16<AV16,BZ16*-1+AV16,"NaN"),"NaN") -> 165.35118 | EV16: =IFERROR(IF(CA16<AY16,CA16*-1+AY16,"NaN"),"NaN") -> NaN | EW16: =IFERROR(IF(CB16<AZ16,CB16*-1+AZ16,"NaN"),"NaN") -> 0.23330535 | EX16: =IFERROR(IF(CC16<BB16,CC16*-1+BB16,"NaN"),"NaN") -> 0.007109334 | EY16: =IFERROR(IF(CD16<BC16,CD16*-1+BC16,"NaN"),"NaN") -> 10.72744
